Workbook

Sheet 외화보유비중 산출
B2: 사업계획 영업이익 | C2: 예상 이자수익 | D2: 위험포션 | E2: 허용가능 최대손익
B3: 4300000000 | C3: 2300000000 | D3: 0.5 | E3: =SUM(B3:C3)*D3 -> 3300000000 | G3: 現외화보유현황[AS-IS]
G4: 통화별 | H4: 환율 | I4: 현재통화별잔액
B5: 최대 환율 변동폭 | C5: 적정 외화보유한도 | G5: 24006005288 | H5: =G5/I5 -> 1472.3834 | I5: 16304181
B6: =E18 -> 0.14642519 | C6: =E3/B6 -> 2.2537106e+10 | D6: =C6/1450 -> 15542832 | G6: 4899884732 | H6: =G6/I6 -> 1691.0276 | I6: 2897578.3
G7: 178265575 | H7: =G7/I7 -> 9.1762787 | I7: 19426783
B8: 현재 자금 총액 | C8: 전체 자금대비 외화비율 | G8: =SUM(G5:G7) -> 29084155595
B9: 90000000000 | C9: =+C6/B9 -> 0.25041229
B11: ※ 최대환율 변동폭 계산 | G11: 외화 통화별 적정보유량[TO-BE]
B12: 1년 간 환율 변동의 표준편차 계산 | C12: 표준편차 | D12: 가중치(보유비율) | E12: 가중치 반영 표준편차 | G12: 통화별 | H12: 환율 | I12: 통화별 유지목표 | L12: USD | M12: 13072096 | O12: (외화MMDA 6.2백만불, 외화정기예금 1백만불 포함)
B13: USD | C13: =데이터!E2 -> 0.08245805 | D13: 0.8 | E13: =+C13*D13 -> 0.06596644 | G13: =+$C$6*D13 -> 1.8029685e+10 | H13: ='매매기준율표(통화명_환율(원)_전일대비)'!B2 -> 1503.5 | I13: =G13/H13 -> 11991809 | L13: EUR | M13: 2460838.8
B14: EUR | C14: =데이터!E3 -> 0.1144367 | D14: 0.18 | E14: =+C14*D14 -> 0.020598607 | G14: =+$C$6*D14 -> 4.0566791e+09 | H14: ='재정된 매매기준율'!B3 -> 1728.48 | I14: =G14/H14 -> 2346963.3 | L14: JPY | M14: 20426738
B15: JPY | C15: =데이터!E4 -> 0.1088746 | D15: 0.02 | E15: =+C15*D15 -> 0.0021774919 | G15: =+$C$6*D15 -> 4.5074212e+08 | H15: ='재정된 매매기준율'!B2/100 -> 9.4978 | I15: =G15/H15 -> 47457529
B16: GBP | C16: =데이터!E5 -> 0.13025665 | D16: 0 | E16: =+C16*D16 -> 0 | G16: =SUM(G13:G15) -> 2.2537106e+10
B17: 전체 통화 변동율(표준편차) | E17: =SUM(E13:E16) -> 0.088742539
B18: 적용 최대 환율 변동폭 | D18: 일반적(95%신뢰도) | E18: =IF($D$18="보수적(99%신뢰도)",$E$17*2.33,$E$17*1.65) -> 0.14642519 | G18: 환전금액(KRW) | H18: 환전금액(USD) | I18: 환전환율 | J18: 환차익
G19: =+G5-G13 -> 5.9763205e+09 | H19: =+G19/H13 -> 3974938.8 | I19: 1510 | J19: =(I19-H5)*H19 -> 1.4952382e+08
B20: 변수 목록:
B21: 예상 사업계획 영업이익, 예상 이자수익, 자금보유액
B23: 상수화 필요: 위험포션 → 의사결정의 영역. 영업이익+이자수익의 어느정도까지는 환리스크 노출 하겠다!
B25: 상수 목록: 월 또는 분기별 Back Data 업데이트
B26: 최대 환율 변동폭: 지난 1년 간 주요통화의 변동성을 표준편차로 구했고, 회사의 보유외화 비율에 따라 가중치를 반영.
B27: 이후, 해당 표준편차의 신뢰도 부여를 위한 추가 가중치를 설정하여 적용할 최대 환율 변동폭을 산출함.(현재는 신뢰도 95% 수준으로 설정)

Sheet 데이터
A1: URL: | B1: https://ecos.bok.or.kr/#/SearchStat
D2: 원/달러 변동율 | E2: =F2*(SQRT(COUNTA(F2:IR2))) -> 0.08245805 | F2: =_xlfn.STDEV.S(G2:IR2) -> 0.0052466801 | G2: =(G8-F8)/F8 -> 0.011149346 | H2: =(H8-G8)/G8 -> -0.0057173972 | I2: =(I8-H8)/H8 -> -0.0073932092 | J2: =(J8-I8)/I8 -> -0.002 | K2: =(K8-J8)/J8 -> 0.00020731117 | L2: =(L8-K8)/K8 -> 0.0041453641 | M2: =(M8-L8)/L8 -> 6.8804183e-05 | N2: =(N8-M8)/M8 -> -0.00061919505 | ... IR2: =(IR8-IQ8)/IQ8 -> 0.0067974772
D3: 원/유로 변동율 | E3: =F3*(SQRT(COUNTA(F3:IR3))) -> 0.1144367 | F3: =_xlfn.STDEV.S(G3:IR3) -> 0.0072814331 | G3: =(G11-F11)/F11 -> 0.019275897 | H3: =(H11-G11)/G11 -> -0.0029271501 | I3: =(I11-H11)/H11 -> -0.0051457976 | J3: =(J11-I11)/I11 -> -0.0034416446 | K3: =(K11-J11)/J11 -> -0.0074926305 | L3: =(L11-K11)/K11 -> 0.0041433408 | M3: =(M11-L11)/L11 -> 0.0056952855 | N3: =(N11-M11)/M11 -> 0.0016464621 | ... IR3: =(IR11-IQ11)/IQ11 -> -0.0041736667
D4: 원/파운드 변동율 | E4: =F4*(SQRT(COUNTA(F4:IR4))) -> 0.1088746 | F4: =_xlfn.STDEV.S(G4:IR4) -> 0.0069275247 | G4: =(G20-F20)/F20 -> 0.021897362 | H4: =(H20-G20)/G20 -> -0.0035203376 | I4: =(I20-H20)/H20 -> -0.0056008733 | J4: =(J20-I20)/I20 -> -0.0073922062 | K4: =(K20-J20)/J20 -> -0.003690283 | L4: =(L20-K20)/K20 -> 0.0026050383 | M4: =(M20-L20)/L20 -> 0.0065374023 | N4: =(N20-M20)/M20 -> -0.00086230722 | ... IR4: =(IR20-IQ20)/IQ20 -> -0.0037754615
D5: 원/엔화 변동율 | E5: =F5*(SQRT(COUNTA(F5:IR5))) -> 0.13025665 | F5: =_xlfn.STDEV.S(G5:IR5) -> 0.0082880319 | G5: =(G10-F10)/F10 -> 0.01287517 | H5: =(H10-G10)/G10 -> -0.001983206 | I5: =(I10-H10)/H10 -> 0.0046507695 | J5: =(J10-I10)/I10 -> 0.0063125999 | K5: =(K10-J10)/J10 -> -0.0021746403 | L5: =(L10-K10)/K10 -> 0.0021689019 | M5: =(M10-L10)/L10 -> -0.0038370257 | N5: =(N10-M10)/M10 -> -0.011922754 | ... IR5: =(IR10-IQ10)/IQ10 -> -0.0095188071
A7: 통계표 | B7: 코드(계정항목) | C7: 계정항목 | D7: 단위 | E7: 변환 | F7: 2025/02/03 | G7: 2025/02/04 | H7: 2025/02/05 | I7: 2025/02/06 | J7: 2025/02/07 | K7: 2025/02/10 | L7: 2025/02/11 | M7: 2025/02/12 | N7: 2025/02/13 | O7: 2025/02/14 | P7: 2025/02/17 | Q7: 2025/02/18 | R7: 2025/02/19 | S7: 2025/02/20 | T7: 2025/02/21 | U7: 2025/02/24 | V7: 2025/02/25 | W7: 2025/02/26 | X7: 2025/02/27 | Y7: 2025/02/28 | Z7: 2025/03/04 | AA7: 2025/03/05 | AB7: 2025/03/06 | AC7: 2025/03/07 | AD7: 2025/03/10 | AE7: 2025/03/11 | AF7: 2025/03/12 | AG7: 2025/03/13 | AH7: 2025/03/14 | AI7: 2025/03/17 | AJ7: 2025/03/18 | AK7: 2025/03/19 | AL7: 2025/03/20 | AM7: 2025/03/21 | AN7: 2025/03/24 | AO7: 2025/03/25 | AP7: 2025/03/26 | AQ7: 2025/03/27 | AR7: 2025/03/28 | AS7: 2025/03/31 | AT7: 2025/04/01 | AU7: 2025/04/02 | AV7: 2025/04/03 | AW7: 2025/04/04 | AX7: 2025/04/07 | AY7: 2025/04/08 | AZ7: 2025/04/09 | BA7: 2025/04/10 | BB7: 2025/04/11 | BC7: 2025/04/14 | BD7: 2025/04/15 | BE7: 2025/04/16 | BF7: 2025/04/17 | BG7: 2025/04/18 | BH7: 2025/04/21 | BI7: 2025/04/22 | BJ7: 2025/04/23 | BK7: 2025/04/24 | BL7: 2025/04/25 | BM7: 2025/04/28 | BN7: 2025/04/29 | BO7: 2025/04/30 | BP7: 2025/05/02 | BQ7: 2025/05/07 | BR7: 2025/05/08 | BS7: 2025/05/09 | BT7: 2025/05/12 | BU7: 2025/05/13 | BV7: 2025/05/14 | BW7: 2025/05/15 | BX7: 2025/05/16 | BY7: 2025/05/19 | BZ7: 2025/05/20 | CA7: 2025/05/21 | CB7: 2025/05/22 | CC7: 2025/05/23 | CD7: 2025/05/26 | CE7: 2025/05/27 | CF7: 2025/05/28 | CG7: 2025/05/29 | CH7: 2025/05/30 | CI7: 2025/06/02 | CJ7: 2025/06/04 | CK7: 2025/06/05 | CL7: 2025/06/09 | CM7: 2025/06/10 | CN7: 2025/06/11 | CO7: 2025/06/12 | CP7: 2025/06/13 | CQ7: 2025/06/16 | CR7: 2025/06/17 | CS7: 2025/06/18 | CT7: 2025/06/19 | CU7: 2025/06/20 | CV7: 2025/06/23 | CW7: 2025/06/24 | CX7: 2025/06/25 | CY7: 2025/06/26 | CZ7: 2025/06/27 | DA7: 2025/06/30 | DB7: 2025/07/01 | DC7: 2025/07/02 | DD7: 2025/07/03 | DE7: 2025/07/04 | DF7: 2025/07/07 | DG7: 2025/07/08 | DH7: 2025/07/09 | DI7: 2025/07/10 | DJ7: 2025/07/11 | DK7: 2025/07/14 | DL7: 2025/07/15 | DM7: 2025/07/16 | DN7: 2025/07/17 | DO7: 2025/07/18 | DP7: 2025/07/21 | DQ7: 2025/07/22 | DR7: 2025/07/23 | DS7: 2025/07/24 | DT7: 2025/07/25 | DU7: 2025/07/28 | DV7: 2025/07/29 | DW7: 2025/07/30 | DX7: 2025/07/31 | DY7: 2025/08/01 | DZ7: 2025/08/04 | EA7: 2025/08/05 | EB7: 2025/08/06 | EC7: 2025/08/07 | ED7: 2025/08/08 | EE7: 2025/08/11 | EF7: 2025/08/12 | EG7: 2025/08/13 | EH7: 2025/08/14 | EI7: 2025/08/18 | EJ7: 2025/08/19 | EK7: 2025/08/20 | EL7: 2025/08/21 | EM7: 2025/08/22 | EN7: 2025/08/25 | EO7: 2025/08/26 | EP7: 2025/08/27 | EQ7: 2025/08/28 | ER7: 2025/08/29 | ES7: 2025/09/01 | ET7: 2025/09/02 | EU7: 2025/09/03 | EV7: 2025/09/04 | EW7: 2025/09/05 | EX7: 2025/09/08 | EY7: 2025/09/09 | EZ7: 2025/09/10 | FA7: 2025/09/11 | FB7: 2025/09/12 | FC7: 2025/09/15 | FD7: 2025/09/16 | FE7: 2025/09/17 | FF7: 2025/09/18 | FG7: 2025/09/19 | FH7: 2025/09/22 | FI7: 2025/09/23 | FJ7: 2025/09/24 | FK7: 2025/09/25 | FL7: 2025/09/26 | FM7: 2025/09/29 | FN7: 2025/09/30 | FO7: 2025/10/01 | FP7: 2025/10/02 | FQ7: 2025/10/10 | FR7: 2025/10/13 | FS7: 2025/10/14 | FT7: 2025/10/15 | FU7: 2025/10/16 | FV7: 2025/10/17 | FW7: 2025/10/20 | FX7: 2025/10/21 | FY7: 2025/10/22 | FZ7: 2025/10/23 | GA7: 2025/10/24 | GB7: 2025/10/27 | GC7: 2025/10/28 | GD7: 2025/10/29 | GE7: 2025/10/30 | GF7: 2025/10/31 | GG7: 2025/11/03 | GH7: 2025/11/04 | GI7: 2025/11/05 | GJ7: 2025/11/06 | GK7: 2025/11/07 | GL7: 2025/11/10 | GM7: 2025/11/11 | GN7: 2025/11/12 | GO7: 2025/11/13 | GP7: 2025/11/14 | GQ7: 2025/11/17 | GR7: 2025/11/18 | GS7: 2025/11/19 | GT7: 2025/11/20 | GU7: 2025/11/21 | GV7: 2025/11/24 | GW7: 2025/11/25 | GX7: 2025/11/26 | GY7: 2025/11/27 | GZ7: 2025/11/28 | HA7: 2025/12/01 | HB7: 2025/12/02 | HC7: 2025/12/03 | HD7: 2025/12/04 | HE7: 2025/12/05 | HF7: 2025/12/08 | HG7: 2025/12/09 | HH7: 2025/12/10 | HI7: 2025/12/11 | HJ7: 2025/12/12 | HK7: 2025/12/15 | HL7: 2025/12/16 | HM7: 2025/12/17 | HN7: 2025/12/18 | HO7: 2025/12/19 | HP7: 2025/12/22 | HQ7: 2025/12/23 | HR7: 2025/12/24 | HS7: 2025/12/26 | HT7: 2025/12/29 | HU7: 2025/12/30 | HV7: 2025/12/31 | HW7: 2026/01/02 | HX7: 2026/01/05 | HY7: 2026/01/06 | HZ7: 2026/01/07 | IA7: 2026/01/08 | IB7: 2026/01/09 | IC7: 2026/01/12 | ID7: 2026/01/13 | IE7: 2026/01/14 | IF7: 2026/01/15 | IG7: 2026/01/16 | IH7: 2026/01/19 | II7: 2026/01/20 | IJ7: 2026/01/21 | IK7: 2026/01/22 | IL7: 2026/01/23 | IM7: 2026/01/26 | IN7: 2026/01/27 | IO7: 2026/01/28 | IP7: 2026/01/29 | IQ7: 2026/01/30 | IR7: 2026/02/02
A8: 3.1.1.1. 주요국 통화의 대원화환율 | B8: 1 | C8: 원/미국달러(매매기준율) | D8: 원 | E8: 원자료 | F8: 1453 | G8: 1469.2 | H8: 1460.8 | I8: 1450 | J8: 1447.1 | K8: 1447.4 | L8: 1453.4 | M8: 1453.5 | N8: 1452.6 | O8: 1450.5 | P8: 1443.3 | Q8: 1441.1 | R8: 1443.9 | S8: 1440.6 | T8: 1439.4 | U8: 1434.1 | V8: 1429.2 | W8: 1430.7 | X8: 1431.8 | Y8: 1439.6 | Z8: 1458.7 | AA8: 1459.6 | AB8: 1456 | AC8: 1441.6 | AD8: 1446.3 | AE8: 1451.5 | AF8: 1457.9 | AG8: 1452 | AH8: 1451.9 | AI8: 1454.8 | AJ8: 1448 | AK8: 1447.1 | AL8: 1452.3 | AM8: 1459.2 | AN8: 1466.9 | AO8: 1466.9 | AP8: 1469.6 | AQ8: 1465.3 | AR8: 1466.8 | AS8: 1466.5 | AT8: 1470.6 | AU8: 1471.7 | AV8: 1467.8 | AW8: 1467 | AX8: 1439.3 | AY8: 1465.9 | AZ8: 1470.2 | BA8: 1482.9 | BB8: 1458.5 | BC8: 1450.8 | BD8: 1427.4 | BE8: 1423.3 | BF8: 1427.4 | BG8: 1419.9 | BH8: 1421.5 | BI8: 1418.9 | BJ8: 1422.6 | BK8: 1426.6 | BL8: 1430.2 | BM8: 1434.6 | BN8: 1439.3 | BO8: 1438.5 | BP8: 1426.9 | BQ8: 1426.6 | BR8: 1394.1 | BS8: 1396 | BT8: 1405.6 | BU8: 1400.4 | BV8: 1413.7 | BW8: 1415.8 | BX8: 1399.6 | BY8: 1394.3 | BZ8: 1398 | CA8: 1392.6 | CB8: 1387.1 | CC8: 1378.4 | CD8: 1376.9 | CE8: 1365 | CF8: 1368.3 | CG8: 1374.6 | CH8: 1381.4 | CI8: 1375.7 | CJ8: 1376.9 | CK8: 1373.8 | CL8: 1359 | CM8: 1358.9 | CN8: 1359.9 | CO8: 1368.8 | CP8: 1362.9 | CQ8: 1366.8 | CR8: 1363.6 | CS8: 1361.7 | CT8: 1373.2 | CU8: 1379.6 | CV8: 1369.4 | CW8: 1381.9 | CX8: 1365 | CY8: 1360.9 | CZ8: 1357.6 | DA8: 1356.4 | DB8: 1353.6 | DC8: 1352.6 | DD8: 1359.4 | DE8: 1358.1 | DF8: 1364.2 | DG8: 1366.6 | DH8: 1368 | DI8: 1373.8 | DJ8: 1373 | DK8: 1374.7 | DL8: 1378.5 | DM8: 1382.7 | DN8: 1387.1 | DO8: 1390.8 | DP8: 1391.9 | DQ8: 1391.1 | DR8: 1386.3 | DS8: 1379.1 | DT8: 1368.7 | DU8: 1376 | DV8: 1379.6 | DW8: 1391.4 | DX8: 1382.9 | DY8: 1390.4 | DZ8: 1399.3 | EA8: 1384.9 | EB8: 1386.7 | EC8: 1389.5 | ED8: 1384.2 | EE8: 1386 | EF8: 1388.3 | EG8: 1390.2 | EH8: 1383.8 | EI8: 1382.2 | EJ8: 1385.3 | EK8: 1389.4 | EL8: 1397.5 | EM8: 1398.1 | EN8: 1395.6 | EO8: 1386.3 | EP8: 1391.2 | EQ8: 1395.7 | ER8: 1388.6 | ES8: 1387.7 | ET8: 1392.4 | EU8: 1392.2 | EV8: 1393.8 | EW8: 1392.7 | EX8: 1391.8 | EY8: 1390.4 | EZ8: 1386.6 | FA8: 1387.6 | FB8: 1389.4 | FC8: 1388.7 | FD8: 1389.5 | FE8: 1382.3 | FF8: 1380 | FG8: 1384.6 | FH8: 1393.6 | FI8: 1394 | FJ8: 1393.8 | FK8: 1394.9 | FL8: 1400.4 | FM8: 1411.6 | FN8: 1402.2 | FO8: 1403.2 | FP8: 1406 | FQ8: 1401.9 | FR8: 1420.5 | FS8: 1427.7 | FT8: 1428.4 | FU8: 1424.4 | FV8: 1419.1 | FW8: 1419.5 | FX8: 1420.2 | FY8: 1423.7 | FZ8: 1430.1 | GA8: 1436.6 | GB8: 1436.1 | GC8: 1432.5 | GD8: 1434.3 | GE8: 1433 | GF8: 1423.2 | GG8: 1427.4 | GH8: 1429 | GI8: 1437.7 | GJ8: 1447 | GK8: 1445.6 | GL8: 1454 | GM8: 1453.7 | GN8: 1463.2 | GO8: 1466.4 | GP8: 1469.5 | GQ8: 1458.5 | GR8: 1458.3 | GS8: 1465.2 | GT8: 1465 | GU8: 1468.4 | GV8: 1472 | GW8: 1473.5 | GX8: 1473.5 | GY8: 1462.7 | GZ8: 1464.8 | HA8: 1465.9 | HB8: 1469.1 | HC8: 1469.6 | HD8: 1468.7 | HE8: 1471.5 | HF8: 1472.1 | HG8: 1469 | HH8: 1470.4 | HI8: 1470.4 | HJ8: 1469.5 | HK8: 1472.5 | HL8: 1474.1 | HM8: 1472.4 | HN8: 1478.6 | HO8: 1477.2 | HP8: 1477.8 | HQ8: 1478.9 | HR8: 1483.4 | HS8: 1460.6 | HT8: 1442.3 | HU8: 1433.9 | HV8: 1434.9 | HW8: 1434.9 | HX8: 1442.1 | HY8: 1446.8 | HZ8: 1445.7 | IA8: 1448.3 | IB8: 1449.4 | IC8: 1455.7 | ID8: 1464.1 | IE8: 1472.8 | IF8: 1477.5 | IG8: 1469.7 | IH8: 1473.5 | II8: 1473.6 | IJ8: 1477 | IK8: 1472.8 | IL8: 1468.4 | IM8: 1467.2 | IN8: 1442.8 | IO8: 1448.8 | IP8: 1428.6 | IQ8: 1427 | IR8: 1436.7
A9: 3.1.1.1. 주요국 통화의 대원화환율 | B9: 53 | C9: 원/위안(매매기준율) | D9: 원 | E9: 원자료 | F9: 199.38 | G9: 199.91 | H9: 199.73 | I9: 198.79 | J9: 198.79 | K9: 198.55 | L9: 198.78 | M9: 198.86 | N9: 198.56 | O9: 198.76 | P9: 198.15 | Q9: 198.72 | R9: 198.44 | S9: 197.86 | T9: 197.81 | U9: 197.9 | V9: 197.52 | W9: 197.21 | X9: 197.34 | Y9: 197.58 | Z9: 199.72 | AA9: 200.34 | AB9: 200.34 | AC9: 198.84 | AD9: 199.55 | AE9: 200.13 | AF9: 201.01 | AG9: 200.72 | AH9: 200.34 | AI9: 200.78 | AJ9: 200.11 | AK9: 199.98 | AL9: 200.67 | AM9: 201.7 | AN9: 202.41 | AO9: 202.04 | AP9: 202.24 | AQ9: 201.49 | AR9: 201.63 | AS9: 201.68 | AT9: 202.68 | AU9: 202.08 | AV9: 201.43 | AW9: 200.7 | AX9: 198.42 | AY9: 200 | AZ9: 200.18 | BA9: 200.82 | BB9: 198.19 | BC9: 198.29 | BD9: 195.44 | BE9: 194.4 | BF9: 194.77 | BG9: 194.33 | BH9: 194.77 | BI9: 194.46 | BJ9: 194.92 | BK9: 195.64 | BL9: 195.93 | BM9: 196.76 | BN9: 197.4 | BO9: 197.7 | BP9: 196.6 | BQ9: 196.92 | BR9: 193.23 | BS9: 192.84 | BT9: 193.81 | BU9: 193.99 | BV9: 196.71 | BW9: 196.32 | BX9: 194.03 | BY9: 193.86 | BZ9: 193.86 | CA9: 193.13 | CB9: 192.4 | CC9: 191.6 | CD9: 191.05 | CE9: 190.19 | CF9: 190.43 | CG9: 191.27 | CH9: 191.88 | CI9: 191.17 | CJ9: 190.9 | CK9: 190.98 | CL9: 189.25 | CM9: 188.84 | CN9: 189.18 | CO9: 190.62 | CP9: 189.39 | CQ9: 190.88 | CR9: 189.93 | CS9: 189.65 | CT9: 190.85 | CU9: 191.86 | CV9: 190.76 | CW9: 192.32 | CX9: 190.31 | CY9: 190.07 | CZ9: 189.56 | DA9: 189.16 | DB9: 189.23 | DC9: 189.02 | DD9: 189.68 | DE9: 189.69 | DF9: 190.55 | DG9: 190.67 | DH9: 190.61 | DI9: 191.21 | DJ9: 191.27 | DK9: 191.92 | DL9: 192.2 | DM9: 192.68 | DN9: 193.15 | DO9: 193.66 | DP9: 193.63 | DQ9: 193.81 | DR9: 193.11 | DS9: 192.37 | DT9: 191.35 | DU9: 192.26 | DV9: 192.64 | DW9: 193.74 | DX9: 192.68 | DY9: 193.18 | DZ9: 193.95 | EA9: 192.7 | EB9: 193.2 | EC9: 193.15 | ED9: 192.97 | EE9: 193 | EF9: 193.05 | EG9: 193.24 | EH9: 192.66 | EI9: 192.94 | EJ9: 192.78 | EK9: 193.29 | EL9: 194.56 | EM9: 194.8 | EN9: 194.46 | EO9: 193.71 | EP9: 194.35 | EQ9: 195.11 | ER9: 194.14 | ES9: 194.72 | ET9: 195.35 | EU9: 194.95 | EV9: 195.18 | EW9: 194.99 | EX9: 195.18 | EY9: 194.89 | EZ9: 194.71 | FA9: 194.78 | FB9: 195.15 | FC9: 195.17 | FD9: 194.99 | FE9: 194.32 | FF9: 194.34 | FG9: 194.71 | FH9: 195.98 | FI9: 195.79 | FJ9: 195.92 | FK9: 195.93 | FL9: 196.34 | FM9: 197.71 | FN9: 196.82 | FO9: 196.73 | FP9: 197.49 | FQ9: 196.59 | FR9: 199.24 | FS9: 200.16 | FT9: 199.87 | FU9: 199.57 | FV9: 199.06 | FW9: 199.31 | FX9: 199.47 | FY9: 199.91 | FZ9: 200.69 | GA9: 201.3 | GB9: 201.38 | GC9: 201.33 | GD9: 202.22 | GE9: 201.97 | GF9: 200.45 | GG9: 200.76 | GH9: 200.62 | GI9: 201.9 | GJ9: 202.91 | GK9: 202.87 | GL9: 204.45 | GM9: 204.19 | GN9: 205.53 | GO9: 206.16 | GP9: 206.48 | GQ9: 204.86 | GR9: 205.3 | GS9: 206.23 | GT9: 206.1 | GU9: 206.32 | GV9: 206.82 | GW9: 207.46 | GX9: 207.78 | GY9: 206.93 | GZ9: 207.05 | HA9: 207.13 | HB9: 207.83 | HC9: 207.6 | HD9: 207.98 | HE9: 208.3 | HF9: 208.17 | HG9: 207.96 | HH9: 208.04 | HI9: 208.4 | HJ9: 208.08 | HK9: 208.85 | HL9: 209.08 | HM9: 209.35 | HN9: 210.24 | HO9: 210.03 | HP9: 210.11 | HQ9: 210.33 | HR9: 211.1 | HS9: 208.37 | HT9: 205.38 | HU9: 204.53 | HV9: 204.76 | HW9: 204.76 | HX9: 206.92 | HY9: 207.52 | HZ9: 207.26 | IA9: 207.47 | IB9: 207.26 | IC9: 208.44 | ID9: 210.64 | IE9: 211.25 | IF9: 211.83 | IG9: 211.18 | IH9: 211.63 | II9: 211.87 | IJ9: 212.48 | IK9: 211.43 | IL9: 211.26 | IM9: 210.93 | IN9: 207.21 | IO9: 208.18 | IP9: 205.78 | IQ9: 205.46 | IR9: 206.79
A10: 3.1.1.1. 주요국 통화의 대원화환율 | B10: 2 | C10: 원/일본엔(100엔) | D10: 원 | E10: 원자료 | F10: 935.91 | G10: 947.96 | H10: 946.08 | I10: 950.48 | J10: 956.48 | K10: 954.4 | L10: 956.47 | M10: 952.8 | N10: 941.44 | O10: 948.47 | P10: 947.79 | Q10: 950.97 | R10: 949.68 | S10: 952.12 | T10: 962.91 | U10: 961.26 | V10: 953.59 | W10: 959.69 | X10: 961.49 | Y10: 961.82 | Z10: 976.37 | AA10: 973.42 | AB10: 978.26 | AC10: 974.28 | AD10: 980.54 | AE10: 988.29 | AF10: 986 | AG10: 979.86 | AH10: 981.64 | AI10: 979.33 | AJ10: 969.37 | AK10: 968.74 | AL10: 976.7 | AM10: 981.14 | AN10: 980.65 | AO10: 973.36 | AP10: 980.09 | AQ10: 974.37 | AR10: 971.26 | AS10: 981.76 | AT10: 980.11 | AU10: 982.48 | AV10: 989.95 | AW10: 1006 | AX10: 992.45 | AY10: 990.91 | AZ10: 1008.61 | BA10: 1004.81 | BB10: 1012.07 | BC10: 1009.74 | BD10: 996.41 | BE10: 993.89 | BF10: 1006.42 | BG10: 997.26 | BH10: 1003.53 | BI10: 1007.99 | BJ10: 996.99 | BK10: 997.03 | BL10: 1001.68 | BM10: 997.88 | BN10: 1011.85 | BO10: 1011.07 | BP10: 980.89 | BQ10: 995.92 | BR10: 969.17 | BS10: 956.69 | BT10: 964.23 | BU10: 943.38 | BV10: 958.67 | BW10: 966.12 | BX10: 961.96 | BY10: 960.43 | BZ10: 964.5 | CA10: 964.5 | CB10: 962.96 | CC10: 958.59 | CD10: 964.05 | CE10: 956.62 | CF10: 948.79 | CG10: 946.56 | CH10: 959.27 | CI10: 956.78 | CJ10: 956.75 | CK10: 962.18 | CL10: 939.48 | CM10: 939.47 | CN10: 938.35 | CO10: 948.94 | CP10: 950.22 | CQ10: 945.59 | CR10: 942.66 | CS10: 936.87 | CT10: 946.87 | CU10: 948.6 | CV10: 935.54 | CW10: 947.16 | CX10: 941.9 | CY10: 938.2 | CZ10: 939.26 | DA10: 938.98 | DB10: 940.65 | DC10: 943.01 | DD10: 946.82 | DE10: 937.43 | DF10: 943.95 | DG10: 936.77 | DH10: 932.77 | DI10: 939.25 | DJ10: 939.32 | DK10: 932.16 | DL10: 932.52 | DM10: 928.77 | DN10: 937.9 | DO10: 937.73 | DP10: 936.64 | DQ10: 943.66 | DR10: 945.02 | DS10: 941.94 | DT10: 930.96 | DU10: 931.21 | DV10: 928.96 | DW10: 936.88 | DX10: 926.1 | DY10: 922.78 | DZ10: 950.1 | EA10: 943.42 | EB10: 939.66 | EC10: 943.89 | ED10: 942.5 | EE10: 938.07 | EF10: 936.74 | EG10: 940.72 | EH10: 940.05 | EI10: 938.52 | EJ10: 936.39 | EK10: 940.95 | EL10: 948.13 | EM10: 942.15 | EN10: 948.65 | EO10: 937.92 | EP10: 943.51 | EQ10: 947.52 | ER10: 944.79 | ES10: 943.05 | ET10: 946.25 | EU10: 937.41 | EV10: 941.72 | EW10: 937.88 | EX10: 938.28 | EY10: 943.25 | EZ10: 940.93 | FA10: 941.7 | FB10: 943.79 | FC10: 940.15 | FD10: 942.7 | FE10: 943.77 | FF10: 939.83 | FG10: 935.76 | FH10: 941.53 | FI10: 943.68 | FJ10: 944.02 | FK10: 937.31 | FL10: 935.19 | FM10: 944.44 | FN10: 943.73 | FO10: 949.26 | FP10: 956.43 | FQ10: 915.08 | FR10: 935.49 | FS10: 937 | FT10: 940.88 | FU10: 943.59 | FV10: 944.68 | FW10: 940.66 | FX10: 941.9 | FY10: 937.2 | FZ10: 941.2 | GA10: 941.23 | GB10: 937.77 | GC10: 937.75 | GD10: 942.84 | GE10: 938.38 | GF10: 923.62 | GG10: 926.1 | GH10: 926.69 | GI10: 935.61 | GJ10: 939.43 | GK10: 944.87 | GL10: 945.54 | GM10: 943.26 | GN10: 949.33 | GO10: 947.75 | GP10: 950.67 | GQ10: 944.1 | GR10: 939.51 | GS10: 942.13 | GT10: 932.76 | GU10: 933.03 | GV10: 939.94 | GW10: 939.04 | GX10: 944.01 | GY10: 935.56 | GZ10: 937.29 | HA10: 939.47 | HB10: 945.15 | HC10: 942.96 | HD10: 946.33 | HE10: 948.59 | HF10: 948.09 | HG10: 942.06 | HH10: 937.67 | HI10: 942.81 | HJ10: 945.05 | HK10: 945.3 | HL10: 950.39 | HM10: 951.47 | HN10: 950.01 | HO10: 949.63 | HP10: 937.78 | HQ10: 942.15 | HR10: 950.01 | HS10: 937.27 | HT10: 921.77 | HU10: 919.08 | HV10: 917.63 | HW10: 915.06 | HX10: 919.79 | HY10: 924.21 | HZ10: 923.06 | IA10: 924.46 | IB10: 923.89 | IC10: 921.01 | ID10: 925.62 | IE10: 925.33 | IF10: 933.47 | IG10: 926.52 | IH10: 934.58 | II10: 931.74 | IJ10: 934.01 | IK10: 930.41 | IL10: 927.02 | IM10: 948.88 | IN10: 935.7 | IO10: 950.81 | IP10: 931.32 | IQ10: 932.89 | IR10: 924.01
A11: 3.1.1.1. 주요국 통화의 대원화환율 | B11: 3 | C11: 원/유로 | D11: 원 | E11: 원자료 | F11: 1491.5 | G11: 1520.25 | H11: 1515.8 | I11: 1508 | J11: 1502.81 | K11: 1491.55 | L11: 1497.73 | M11: 1506.26 | N11: 1508.74 | O11: 1517.8 | P11: 1514.02 | Q11: 1510.63 | R11: 1508.3 | S11: 1501.61 | T11: 1511.95 | U11: 1502.79 | V11: 1495.51 | W11: 1504.74 | X11: 1501.74 | Y11: 1496.97 | Z11: 1529.37 | AA11: 1552.14 | AB11: 1571.24 | AC11: 1555.92 | AD11: 1569.52 | AE11: 1573.57 | AF11: 1591.44 | AG11: 1581.01 | AH11: 1575.6 | AI11: 1583.26 | AJ11: 1581.14 | AK11: 1583.42 | AL11: 1584.1 | AM11: 1584.33 | AN11: 1587.33 | AO11: 1584.62 | AP11: 1585.33 | AQ11: 1573.15 | AR11: 1583.78 | AS11: 1587.85 | AT11: 1590.9 | AU11: 1589.14 | AV11: 1592.05 | AW11: 1620.89 | AX11: 1582.15 | AY11: 1600.1 | AZ11: 1613.1 | BA11: 1624.22 | BB11: 1635.56 | BC11: 1644.41 | BD11: 1619.31 | BE11: 1606.48 | BF11: 1626.88 | BG11: 1614.78 | BH11: 1626.12 | BI11: 1634.43 | BJ11: 1615.15 | BK11: 1616.98 | BL11: 1628.28 | BM11: 1628.41 | BN11: 1642.1 | BO11: 1638.24 | BP11: 1611.54 | BQ11: 1617.27 | BR11: 1575.82 | BS11: 1567.22 | BT11: 1578.35 | BU11: 1553.25 | BV11: 1581.72 | BW11: 1583.64 | BX11: 1566.43 | BY11: 1560.36 | BZ11: 1570.51 | CA11: 1571.2 | CB11: 1569.85 | CC11: 1555.94 | CD11: 1566.36 | CE11: 1554.74 | CF11: 1551.04 | CG11: 1551.17 | CH11: 1571.14 | CI11: 1562.73 | CJ11: 1566.29 | CK11: 1569.09 | CL11: 1550.21 | CM11: 1552.07 | CN11: 1554.64 | CO11: 1575.08 | CP11: 1579.81 | CQ11: 1576.81 | CR11: 1576.25 | CS11: 1563.03 | CT11: 1576.3 | CU11: 1586.75 | CV11: 1573.17 | CW11: 1602.66 | CX11: 1584.77 | CY11: 1588.17 | CZ11: 1587.1 | DA11: 1591.8 | DB11: 1595.42 | DC11: 1596.34 | DD11: 1604.02 | DE11: 1597.06 | DF11: 1607.1 | DG11: 1603.91 | DH11: 1604.19 | DI11: 1610.64 | DJ11: 1607.1 | DK11: 1604.07 | DL11: 1608.02 | DM11: 1604.49 | DN11: 1614.17 | DO11: 1615.76 | DP11: 1618.29 | DQ11: 1626.82 | DR11: 1628.63 | DS11: 1623.89 | DT11: 1608.91 | DU11: 1617.69 | DV11: 1599.58 | DW11: 1607.07 | DX11: 1579.62 | DY11: 1588.18 | DZ11: 1620.6 | EA11: 1604.13 | EB11: 1605.31 | EC11: 1620.43 | ED11: 1615.71 | EE11: 1614.2 | EF11: 1612.44 | EG11: 1623.41 | EH11: 1620.29 | EI11: 1618.56 | EJ11: 1616.16 | EK11: 1618.1 | EL11: 1628.16 | EM11: 1623.4 | EN11: 1634.6 | EO11: 1610.67 | EP11: 1619.57 | EQ11: 1625.08 | ER11: 1621.61 | ES11: 1621.87 | ET11: 1630.78 | EU11: 1619.76 | EV11: 1625.17 | EW11: 1622.43 | EX11: 1629.45 | EY11: 1635.74 | EZ11: 1623.85 | FA11: 1624.05 | FB11: 1630.88 | FC11: 1628.67 | FD11: 1634.54 | FE11: 1640.58 | FF11: 1631.44 | FG11: 1632.1 | FH11: 1635.95 | FI11: 1645.13 | FJ11: 1646.57 | FK11: 1638.17 | FL11: 1633.99 | FM11: 1652.35 | FN11: 1644.5 | FO11: 1647.71 | FP11: 1650.08 | FQ11: 1620.6 | FR11: 1649.2 | FS11: 1651.14 | FT11: 1657.52 | FU11: 1658.93 | FV11: 1659.92 | FW11: 1654.57 | FX11: 1653.61 | FY11: 1651.56 | FZ11: 1660.49 | GA11: 1668.83 | GB11: 1669.83 | GC11: 1668.93 | GD11: 1671.03 | GE11: 1662.71 | GF11: 1646.5 | GG11: 1646.72 | GH11: 1646.14 | GI11: 1650.91 | GJ11: 1663.25 | GK11: 1669.45 | GL11: 1679.15 | GM11: 1680.4 | GN11: 1694.75 | GO11: 1700 | GP11: 1708.96 | GQ11: 1695.29 | GR11: 1690.46 | GS11: 1696.77 | GT11: 1690.54 | GU11: 1692.4 | GV11: 1694.42 | GW11: 1697.84 | GX11: 1704.99 | GY11: 1696.37 | GZ11: 1699.17 | HA11: 1701.18 | HB11: 1705.55 | HC11: 1708.56 | HD11: 1713.97 | HE11: 1713.19 | HF11: 1713.82 | HG11: 1709.62 | HH11: 1709.78 | HI11: 1720.07 | HJ11: 1725.41 | HK11: 1728.72 | HL11: 1732.73 | HM11: 1730 | HN11: 1736.17 | HO11: 1732.16 | HP11: 1731.02 | HQ11: 1739.78 | HR11: 1749.74 | HS11: 1721.1 | HT11: 1698.45 | HU11: 1688.35 | HV11: 1685.72 | HW11: 1685.72 | HX11: 1688.99 | HY11: 1695.5 | HZ11: 1689.95 | IA11: 1691.18 | IB11: 1690 | IC11: 1693.42 | ID11: 1708.09 | IE11: 1715 | IF11: 1720.62 | IG11: 1706.1 | IH11: 1709.55 | II11: 1715.79 | IJ11: 1731.71 | IK11: 1720.89 | IL11: 1726.62 | IM11: 1744.06 | IN11: 1713.9 | IO11: 1743.05 | IP11: 1707.75 | IQ11: 1708.33 | IR11: 1701.2
A12: 3.1.1.1. 주요국 통화의 대원화환율 | B12: 4 | C12: 원/독일마르크 | D12: 원 | E12: 원자료
A13: 3.1.1.1. 주요국 통화의 대원화환율 | B13: 5 | C13: 원/프랑스프랑 | D13: 원 | E13: 원자료
A14: 3.1.1.1. 주요국 통화의 대원화환율 | B14: 6 | C14: 원/이태리리라(100리라) | D14: 원 | E14: 원자료
A15: 3.1.1.1. 주요국 통화의 대원화환율 | B15: 7 | C15: 원/벨기에프랑 | D15: 원 | E15: 원자료
A16: 3.1.1.1. 주요국 통화의 대원화환율 | B16: 8 | C16: 원/오스트리아실링 | D16: 원 | E16: 원자료
A17: 3.1.1.1. 주요국 통화의 대원화환율 | B17: 9 | C17: 원/네덜란드길더 | D17: 원 | E17: 원자료
A18: 3.1.1.1. 주요국 통화의 대원화환율 | B18: 10 | C18: 원/스페인페세타(100페세타) | D18: 원 | E18: 원자료
A19: 3.1.1.1. 주요국 통화의 대원화환율 | B19: 11 | C19: 원/핀란드마르카 | D19: 원 | E19: 원자료
A20: 3.1.1.1. 주요국 통화의 대원화환율 | B20: 12 | C20: 원/영국파운드 | D20: 원 | E20: 원자료 | F20: 1790.17 | G20: 1829.37 | H20: 1822.93 | I20: 1812.72 | J20: 1799.32 | K20: 1792.68 | L20: 1797.35 | M20: 1809.1 | N20: 1807.54 | O20: 1822.55 | P20: 1816.54 | Q20: 1818.74 | R20: 1823 | S20: 1812.92 | T20: 1823.94 | U20: 1814.21 | V20: 1803.72 | W20: 1812.77 | X20: 1815.38 | Y20: 1814.4 | Z20: 1852.69 | AA20: 1867.56 | AB20: 1877.15 | AC20: 1857.72 | AD20: 1869.85 | AE20: 1869.02 | AF20: 1887.76 | AG20: 1882.52 | AH20: 1880.43 | AI20: 1881.13 | AJ20: 1880.45 | AK20: 1881.3 | AL20: 1888.79 | AM20: 1891.93 | AN20: 1894.21 | AO20: 1895.31 | AP20: 1901.88 | AQ20: 1886.21 | AR20: 1899.14 | AS20: 1897.36 | AT20: 1900.02 | AU20: 1902.1 | AV20: 1911.74 | AW20: 1920.67 | AX20: 1855.04 | AY20: 1866.68 | AZ20: 1878.84 | BA20: 1900.71 | BB20: 1891.6 | BC20: 1897.43 | BD20: 1880.67 | BE20: 1882.67 | BF20: 1889.59 | BG20: 1883.85 | BH20: 1891.23 | BI20: 1898.56 | BJ20: 1888.22 | BK20: 1893.24 | BL20: 1907.17 | BM20: 1907.87 | BN20: 1933.77 | BO20: 1928.6 | BP20: 1895.14 | BQ20: 1903.73 | BR20: 1852.69 | BS20: 1848.86 | BT20: 1868.04 | BU20: 1844.82 | BV20: 1880.72 | BW20: 1878.27 | BX20: 1862.66 | BY20: 1854.42 | BZ20: 1867.24 | CA20: 1865.04 | CB20: 1859.96 | CC20: 1850.36 | CD20: 1864.25 | CE20: 1851.83 | CF20: 1848.98 | CG20: 1850.21 | CH20: 1864.48 | CI20: 1852.79 | CJ20: 1861.98 | CK20: 1861.77 | CL20: 1839.41 | CM20: 1841.51 | CN20: 1836.2 | CO20: 1856.85 | CP20: 1855.79 | CQ20: 1852.56 | CR20: 1851.56 | CS20: 1828.35 | CT20: 1842.7 | CU20: 1858.46 | CV20: 1838.35 | CW20: 1871.02 | CX20: 1858.38 | CY20: 1861.1 | CZ20: 1863.17 | DA20: 1861.86 | DB20: 1858.9 | DC20: 1858.88 | DD20: 1855.72 | DE20: 1854.55 | DF20: 1862.34 | DG20: 1861.04 | DH20: 1859.45 | DI20: 1866.86 | DJ20: 1865.15 | DK20: 1853.78 | DL20: 1850.71 | DM20: 1850.88 | DN20: 1860.66 | DO20: 1868.19 | DP20: 1866.82 | DQ20: 1876.45 | DR20: 1875.11 | DS20: 1873.37 | DT20: 1848.91 | DU20: 1848.66 | DV20: 1843.28 | DW20: 1857.73 | DX20: 1832.69 | DY20: 1836.72 | DZ20: 1857.99 | EA20: 1841.29 | EB20: 1844.17 | EC20: 1856.23 | ED20: 1861.47 | EE20: 1863.2 | EF20: 1864.97 | EG20: 1876.91 | EH20: 1879.34 | EI20: 1874.06 | EJ20: 1871.12 | EK20: 1874.23 | EL20: 1879.92 | EM20: 1875.69 | EN20: 1886.01 | EO20: 1865.27 | EP20: 1875.13 | EQ20: 1884.2 | ER20: 1875.86 | ES20: 1873.88 | ET20: 1886.08 | EU20: 1863.67 | EV20: 1873.48 | EW20: 1871.02 | EX20: 1877.12 | EY20: 1884.06 | EZ20: 1875.86 | FA20: 1878.39 | FB20: 1886.53 | FC20: 1882.52 | FD20: 1890.21 | FE20: 1886.98 | FF20: 1880.94 | FG20: 1876.41 | FH20: 1877.11 | FI20: 1883.99 | FJ20: 1885.04 | FK20: 1876.21 | FL20: 1868.41 | FM20: 1892.39 | FN20: 1883.72 | FO20: 1887.3 | FP20: 1895.5 | FQ20: 1863.9 | FR20: 1896.08 | FS20: 1902.91 | FT20: 1902.63 | FU20: 1908.98 | FV20: 1907.48 | FW20: 1905.68 | FX20: 1903.64 | FY20: 1903.42 | FZ20: 1910.11 | GA20: 1914.41 | GB20: 1913.1 | GC20: 1910.88 | GD20: 1903.46 | GE20: 1890.63 | GF20: 1872.15 | GG20: 1875.82 | GH20: 1877.35 | GI20: 1871.81 | GJ20: 1888.26 | GK20: 1898.8 | GL20: 1911.79 | GM20: 1915.54 | GN20: 1924.03 | GO20: 1925.53 | GP20: 1933.49 | GQ20: 1920.48 | GR20: 1918.47 | GS20: 1926.52 | GT20: 1912.7 | GU20: 1919.2 | GV20: 1927.95 | GW20: 1931.54 | GX20: 1940.53 | GY20: 1937.13 | GZ20: 1939.32 | HA20: 1941 | HB20: 1940.9 | HC20: 1942.08 | HD20: 1960.79 | HE20: 1960.7 | HF20: 1961.57 | HG20: 1957.15 | HH20: 1955.85 | HI20: 1968.13 | HJ20: 1967.95 | HK20: 1968.51 | HL20: 1972.2 | HM20: 1976.77 | HN20: 1977.7 | HO20: 1976.86 | HP20: 1977.44 | HQ20: 1991.71 | HR20: 2004.59 | HS20: 1972.76 | HT20: 1946.6 | HU20: 1936.84 | HV20: 1932.31 | HW20: 1933.31 | HX20: 1940.2 | HY20: 1958.61 | HZ20: 1951.98 | IA20: 1949.19 | IB20: 1947.63 | IC20: 1950.57 | ID20: 1971.26 | IE20: 1977.23 | IF20: 1985.98 | IG20: 1966.46 | IH20: 1971.4 | II20: 1977.79 | IJ20: 1985.46 | IK20: 1977.9 | IL20: 1983.44 | IM20: 2007.06 | IN20: 1973.53 | IO20: 2004.27 | IP20: 1971.83 | IQ20: 1970.62 | IR20: 1963.18
A21: 3.1.1.1. 주요국 통화의 대원화환율 | B21: 13 | C21: 원/캐나다달러 | D21: 원 | E21: 원자료 | F21: 987.7 | G21: 1020.28 | H21: 1019.58 | I21: 1012.85 | J21: 1011.18 | K21: 1009.31 | L21: 1014.77 | M21: 1017.43 | N21: 1015.77 | O21: 1021.95 | P21: 1017.7 | Q21: 1015.79 | R21: 1017.33 | S21: 1011.69 | T21: 1015.66 | U21: 1009.04 | V21: 1001.65 | W21: 999.93 | X21: 998.57 | Y21: 997.44 | Z21: 1006.66 | AA21: 1013.89 | AB21: 1015.94 | AC21: 1008.75 | AD21: 1005.84 | AE21: 1005.44 | AF21: 1010.47 | AG21: 1011.14 | AH21: 1006.27 | AI21: 1012.77 | AJ21: 1012.94 | AK21: 1011.96 | AL21: 1014 | AM21: 1018.6 | AN21: 1023.05 | AO21: 1024.59 | AP21: 1029.46 | AQ21: 1024.15 | AR21: 1025.05 | AS21: 1024.41 | AT21: 1021.89 | AU21: 1029.41 | AV21: 1029.31 | AW21: 1041.53 | AX21: 1010.64 | AY21: 1029.53 | AZ21: 1031.03 | BA21: 1051.37 | BB21: 1044.17 | BC21: 1045.47 | BD21: 1027.13 | BE21: 1019.41 | BF21: 1029.91 | BG21: 1026.05 | BH21: 1027.95 | BI21: 1025.36 | BJ21: 1028.04 | BK21: 1028.14 | BL21: 1032.3 | BM21: 1034.73 | BN21: 1040.67 | BO21: 1039.98 | BP21: 1030.07 | BQ21: 1035.72 | BR21: 1007.55 | BS21: 1002.69 | BT21: 1009.34 | BU21: 1002.11 | BV21: 1014.64 | BW21: 1012.95 | BX21: 1002.94 | BY21: 999.18 | BZ21: 1001.47 | CA21: 1001.19 | CB21: 1000.29 | CC21: 994.66 | CD21: 1003.06 | CE21: 993.74 | CF21: 990.34 | CG21: 993.35 | CH21: 1000.51 | CI21: 1002.33 | CJ21: 1003.64 | CK21: 1004.61 | CL21: 992.26 | CM21: 991.72 | CN21: 994.88 | CO21: 1001.61 | CP21: 1002.02 | CQ21: 1006.18 | CR21: 1004.9 | CS21: 994.92 | CT21: 1002.67 | CU21: 1007.12 | CV21: 996 | CW21: 1006.34 | CX21: 994.46 | CY21: 992.02 | CZ21: 995.02 | DA21: 991.41 | DB21: 994.86 | DC21: 991.1 | DD21: 1000.48 | DE21: 999.85 | DF21: 1002.72 | DG21: 999.78 | DH21: 1001.13 | DI21: 1003.69 | DJ21: 1005.53 | DK21: 1003.72 | DL21: 1005.87 | DM21: 1007.84 | DN21: 1013.44 | DO21: 1012.23 | DP21: 1013.91 | DQ21: 1016.89 | DR21: 1019 | DS21: 1013.9 | DT21: 1003.26 | DU21: 1004.6 | DV21: 1004.48 | DW21: 1010.38 | DX21: 999.96 | DY21: 1003.65 | DZ21: 1015.35 | EA21: 1005.66 | EB21: 1006.79 | EC21: 1011.28 | ED21: 1007.61 | EE21: 1007.67 | EF21: 1007.77 | EG21: 1009.73 | EH21: 1006.14 | EI21: 1000.47 | EJ21: 1003.62 | EK21: 1001.98 | EL21: 1007.28 | EM21: 1005.39 | EN21: 1009.04 | EO21: 1000.4 | EP21: 1005.53 | EQ21: 1012.51 | ER21: 1009.82 | ES21: 1010.01 | ET21: 1012.51 | EU21: 1009.9 | EV21: 1010.44 | EW21: 1007.74 | EX21: 1005.6 | EY21: 1007.5 | EZ21: 1001.48 | FA21: 1001.05 | FB21: 1004.34 | FC21: 1003.4 | FD21: 1008.49 | FE21: 1005.97 | FF21: 1002.14 | FG21: 1003.66 | FH21: 1011.1 | FI21: 1008.46 | FJ21: 1007.3 | FK21: 1003.78 | FL21: 1004.59 | FM21: 1012.41 | FN21: 1007.69 | FO21: 1008.12 | FP21: 1008.86 | FQ21: 999.64 | FR21: 1014.93 | FS21: 1016.95 | FT21: 1017.31 | FU21: 1014.1 | FV21: 1010.25 | FW21: 1013.02 | FX21: 1012.08 | FY21: 1015.48 | FZ21: 1022.27 | GA21: 1027.06 | GB21: 1026.45 | GC21: 1024.31 | GD21: 1028.47 | GE21: 1027.61 | GF21: 1017.73 | GG21: 1018.63 | GH21: 1016.65 | GI21: 1019.32 | GJ21: 1025.66 | GK21: 1024.01 | GL21: 1035.47 | GM21: 1036.84 | GN21: 1043.91 | GO21: 1046.64 | GP21: 1047.06 | GQ21: 1040.08 | GR21: 1037.79 | GS21: 1047.69 | GT21: 1043.15 | GU21: 1041.64 | GV21: 1044.3 | GW21: 1044.44 | GX21: 1045.07 | GY21: 1041.55 | GZ21: 1044.31 | HA21: 1049.24 | HB21: 1049.58 | HC21: 1051.82 | HD21: 1052.79 | HE21: 1054.2 | HF21: 1064.58 | HG21: 1060.42 | HH21: 1062.01 | HI21: 1065.93 | HJ21: 1066.94 | HK21: 1069.28 | HL21: 1070.75 | HM21: 1070.52 | HN21: 1072.54 | HO21: 1072.49 | HP21: 1071.22 | HQ21: 1075.8 | HR21: 1083.6 | HS21: 1068.12 | HT21: 1055.43 | HU21: 1047.52 | HV21: 1047.72 | HW21: 1045.73 | HX21: 1049.53 | HY21: 1050.61 | HZ21: 1046.62 | IA21: 1044.95 | IB21: 1045.52 | IC21: 1046.36 | ID21: 1055.13 | IE21: 1060.56 | IF21: 1064.44 | IG21: 1058.21 | IH21: 1059.16 | II21: 1062.4 | IJ21: 1067.31 | IK21: 1064.58 | IL21: 1065.29 | IM21: 1071.46 | IN21: 1052.29 | IO21: 1066.2 | IP21: 1053.27 | IQ21: 1057.94 | IR21: 1052.07
A22: 3.1.1.1. 주요국 통화의 대원화환율 | B22: 14 | C22: 원/스위스프랑 | D22: 원 | E22: 원자료 | F22: 1589.63 | G22: 1613.88 | H22: 1613.61 | I22: 1608.34 | J22: 1599.45 | K22: 1588.98 | L22: 1594.86 | M22: 1591.83 | N22: 1589.89 | O22: 1605.69 | P22: 1604.47 | Q22: 1599.45 | R22: 1597.5 | S22: 1592.97 | T22: 1603.43 | U22: 1597.79 | V22: 1592.25 | W22: 1602.4 | X22: 1601.12 | Y22: 1599.82 | Z22: 1626.2 | AA22: 1640.37 | AB22: 1634.58 | AC22: 1631.97 | AD22: 1648.58 | AE22: 1648.68 | AF22: 1651.26 | AG22: 1646.91 | AH22: 1644.56 | AI22: 1645.98 | AJ22: 1643.12 | AK22: 1650.15 | AL22: 1656.18 | AM22: 1655.17 | AN22: 1661.08 | AO22: 1661.83 | AP22: 1664.89 | AQ22: 1657.02 | AR22: 1663.7 | AS22: 1665.81 | AT22: 1663.29 | AU22: 1665.1 | AV22: 1669.57 | AW22: 1708.3 | AX22: 1690.31 | AY22: 1705.03 | AZ22: 1737.62 | BA22: 1733.37 | BB22: 1771.21 | BC22: 1774.9 | BD22: 1750.12 | BE22: 1733.72 | BF22: 1754.42 | BG22: 1733.81 | BH22: 1747.82 | BI22: 1755.09 | BJ22: 1722.8 | BK22: 1719.73 | BL22: 1728.13 | BM22: 1731.46 | BN22: 1752.47 | BO22: 1745.96 | BP22: 1721.33 | BQ22: 1726.6 | BR22: 1692.49 | BS22: 1678.89 | BT22: 1685.27 | BU22: 1656.1 | BV22: 1684.28 | BW22: 1683.27 | BX22: 1676.07 | BY22: 1670.12 | BZ22: 1673.95 | CA22: 1683.1 | CB22: 1679.3 | CC22: 1664.63 | CD22: 1675.57 | CE22: 1663.62 | CF22: 1654.43 | CG22: 1658.44 | CH22: 1679.72 | CI22: 1673.8 | CJ22: 1671.91 | CK22: 1678.74 | CL22: 1654.79 | CM22: 1653.87 | CN22: 1653.47 | CO22: 1671.92 | CP22: 1682.28 | CQ22: 1683.77 | CR22: 1675.9 | CS22: 1666.91 | CT22: 1677.5 | CU22: 1688.72 | CV22: 1673.37 | CW22: 1701.53 | CX22: 1695.34 | CY22: 1692.45 | CZ22: 1694.78 | DA22: 1699 | DB22: 1706.83 | DC22: 1709.66 | DD22: 1716.85 | DE22: 1708.41 | DF22: 1717.6 | DG22: 1714.57 | DH22: 1719.02 | DI22: 1730.77 | DJ22: 1723.79 | DK22: 1724.41 | DL22: 1727.66 | DM22: 1724.82 | DN22: 1731.82 | DO22: 1732.76 | DP22: 1736.51 | DQ22: 1743.01 | DR22: 1748.72 | DS22: 1740.96 | DT22: 1721.31 | DU22: 1730.06 | DV22: 1717.1 | DW22: 1727.05 | DX22: 1699 | DY22: 1712.21 | DZ22: 1739.67 | EA22: 1715.79 | EB22: 1717.59 | EC22: 1723.62 | ED22: 1717.69 | EE22: 1715.67 | EF22: 1708.78 | EG22: 1724.28 | EH22: 1718.69 | EI22: 1713.72 | EJ22: 1715.65 | EK22: 1720.09 | EL22: 1737.86 | EM22: 1728.5 | EN22: 1739.39 | EO22: 1719.76 | EP22: 1731.1 | EQ22: 1740.82 | ER22: 1731.85 | ES22: 1732.46 | ET22: 1739.41 | EU22: 1729.33 | EV22: 1733.69 | EW22: 1728.67 | EX22: 1741.16 | EY22: 1753.01 | EZ22: 1739.88 | FA22: 1737.11 | FB22: 1746.03 | FC22: 1743.28 | FD22: 1748.57 | FE22: 1758.2 | FF22: 1750.16 | FG22: 1746.91 | FH22: 1750.75 | FI22: 1759.43 | FJ22: 1760.96 | FK22: 1755.03 | FL22: 1750.94 | FM22: 1769.81 | FN22: 1758.02 | FO22: 1762.48 | FP22: 1764.67 | FQ22: 1737.82 | FR22: 1771.75 | FS22: 1774.75 | FT22: 1782.94 | FU22: 1787.99 | FV22: 1791.34 | FW22: 1787.67 | FX22: 1792.05 | FY22: 1787.33 | FZ22: 1796.38 | GA22: 1806.7 | GB22: 1803.47 | GC22: 1802.45 | GD22: 1807.68 | GE22: 1791.59 | GF22: 1775.34 | GG22: 1774.82 | GH22: 1768.35 | GI22: 1773.84 | GJ22: 1785.65 | GK22: 1792.77 | GL22: 1802.52 | GM22: 1805.61 | GN22: 1827.74 | GO22: 1838.52 | GP22: 1852.86 | GQ22: 1837.83 | GR22: 1831.81 | GS22: 1831.27 | GT22: 1818.86 | GU22: 1822.29 | GV22: 1819.98 | GW22: 1822.62 | GX22: 1824.88 | GY22: 1819.5 | GZ22: 1820.98 | HA22: 1824.73 | HB22: 1825.99 | HC22: 1830.48 | HD22: 1836.91 | HE22: 1830.79 | HF22: 1828.81 | HG22: 1820.66 | HH22: 1823.98 | HI22: 1838.46 | HJ22: 1848.78 | HK22: 1850.69 | HL22: 1851.3 | HM22: 1851.49 | HN22: 1859.06 | HO22: 1859.75 | HP22: 1857.82 | HQ22: 1868.24 | HR22: 1884.16 | HS22: 1854.14 | HT22: 1827.89 | HU22: 1817.94 | HV22: 1811.97 | HW22: 1810.83 | HX22: 1819.57 | HY22: 1826.88 | HZ22: 1817.23 | IA22: 1815.94 | IB22: 1814.13 | IC22: 1816.67 | ID22: 1835.98 | IE22: 1838.82 | IF22: 1847.68 | IG22: 1829.24 | IH22: 1841.18 | II22: 1847.77 | IJ22: 1869.98 | IK22: 1850.83 | IL22: 1861.68 | IM22: 1891.45 | IN22: 1856.77 | IO22: 1901.19 | IP22: 1859.07 | IQ22: 1866.82 | IR22: 1855.72
A23: 3.1.1.1. 주요국 통화의 대원화환율 | B23: 17 | C23: 원/호주달러 | D23: 원 | E23: 원자료 | F23: 894.54 | G23: 915.39 | H23: 913.37 | I23: 911.25 | J23: 908.92 | K23: 905.06 | L23: 912.66 | M23: 914.91 | N23: 912.31 | O23: 915.99 | P23: 916.71 | Q23: 915.46 | R23: 917.09 | S23: 914.13 | T23: 922.22 | U23: 913.74 | V23: 906.76 | W23: 908.28 | X23: 903.32 | Y23: 897.73 | Z23: 907.17 | AA23: 916.26 | AB23: 922.52 | AC23: 913.25 | AD23: 910.66 | AE23: 910.6 | AF23: 918.19 | AG23: 918.68 | AH23: 912.74 | AI23: 920.38 | AJ23: 924.33 | AK23: 920.43 | AL23: 923.3 | AM23: 919.66 | AN23: 920.92 | AO23: 921.87 | AP23: 926.29 | AQ23: 920.21 | AR23: 923.79 | AS23: 920.67 | AT23: 918.24 | AU23: 924.6 | AV23: 917.3 | AW23: 926.85 | AX23: 862.43 | AY23: 879.47 | AZ23: 874.92 | BA23: 910.43 | BB23: 907.11 | BC23: 911.39 | BD23: 902.47 | BE23: 900.66 | BF23: 909.9 | BG23: 906.96 | BH23: 907.56 | BI23: 910.15 | BJ23: 906.05 | BK23: 908.1 | BL23: 916.62 | BM23: 917.07 | BN23: 925.25 | BO23: 918.19 | BP23: 910.65 | BQ23: 927.93 | BR23: 895.92 | BS23: 893.02 | BT23: 902.75 | BU23: 892.19 | BV23: 914.81 | BW23: 909.86 | BX23: 896.23 | BY23: 893.54 | BZ23: 902.34 | CA23: 894.33 | CB23: 892.25 | CC23: 883.62 | CD23: 895.6 | CE23: 885.07 | CF23: 882.07 | CG23: 883.8 | CH23: 890.24 | CI23: 887.05 | CJ23: 889.96 | CK23: 892.08 | CL23: 883.08 | CM23: 885.32 | CN23: 887.33 | CO23: 890.47 | CP23: 890.18 | CQ23: 886.64 | CR23: 889.82 | CS23: 881.22 | CT23: 893.54 | CU23: 894.46 | CV23: 881.96 | CW23: 894.57 | CX23: 886.02 | CY23: 887.03 | CZ23: 888.82 | DA23: 886.61 | DB23: 891.07 | DC23: 890.01 | DD23: 895.37 | DE23: 892.81 | DF23: 893.96 | DG23: 888.22 | DH23: 893.37 | DI23: 898.05 | DJ23: 905.29 | DK23: 902.9 | DL23: 902.02 | DM23: 900.83 | DN23: 904.94 | DO23: 903.6 | DP23: 905.85 | DQ23: 907.62 | DR23: 908.44 | DS23: 910.69 | DT23: 902.73 | DU23: 904.44 | DV23: 900.19 | DW23: 906.01 | DX23: 891.07 | DY23: 894.37 | DZ23: 904.65 | EA23: 896.38 | EB23: 897.47 | EC23: 903.94 | ED23: 903.26 | EE23: 903.6 | EF23: 904.41 | EG23: 907.8 | EH23: 905.97 | EI23: 900.09 | EJ23: 899.34 | EK23: 896.58 | EL23: 898.94 | EM23: 897.93 | EN23: 905.47 | EO23: 898.74 | EP23: 903.79 | EQ23: 908.46 | ER23: 906.76 | ES23: 907.97 | ET23: 912.51 | EU23: 907.51 | EV23: 912.03 | EW23: 907.76 | EX23: 911.56 | EY23: 917.04 | EZ23: 913.21 | FA23: 918.52 | FB23: 925.97 | FC23: 923.07 | FD23: 926.94 | FE23: 924.07 | FF23: 918.67 | FG23: 915.71 | FH23: 918.87 | FI23: 919.97 | FJ23: 919.84 | FK23: 918.54 | FL23: 915.58 | FM23: 924.53 | FN23: 922.37 | FO23: 928.71 | FP23: 929.86 | FQ23: 918.88 | FR23: 922.69 | FS23: 930.08 | FT23: 927.32 | FU23: 927.5 | FV23: 920.57 | FW23: 923.1 | FX23: 925.4 | FY23: 924.27 | FZ23: 927.92 | GA23: 935.73 | GB23: 938.56 | GC23: 939.29 | GD23: 943.91 | GE23: 941.41 | GF23: 932.77 | GG23: 934.02 | GH23: 934.28 | GI23: 933.07 | GJ23: 941.49 | GK23: 936.68 | GL23: 945.03 | GM23: 950.14 | GN23: 955.1 | GO23: 958.44 | GP23: 959.95 | GQ23: 952.91 | GR23: 947.38 | GS23: 953.92 | GT23: 949.76 | GU23: 945.5 | GV23: 951.43 | GW23: 952.91 | GX23: 953.5 | GY23: 953.68 | GZ23: 957.39 | HA23: 960.31 | HB23: 961.23 | HC23: 965.16 | HD23: 969.34 | HE23: 972.29 | HF23: 976.74 | HG23: 973.21 | HH23: 976.71 | HI23: 980.98 | HJ23: 979.35 | HK23: 978.33 | HL23: 979.69 | HM23: 976.42 | HN23: 976.69 | HO23: 976.95 | HP23: 977.05 | HQ23: 985.1 | HR23: 994.03 | HS23: 978.97 | HT23: 968.36 | HU23: 959.92 | HV23: 961.02 | HW23: 957.51 | HX23: 964.55 | HY23: 971.38 | HZ23: 974.55 | IA23: 973.55 | IB23: 971.17 | IC23: 973.57 | ID23: 982.26 | IE23: 984.94 | IF23: 987.12 | IG23: 984.77 | IH23: 984.22 | II23: 989.15 | IJ23: 994.69 | IK23: 995.32 | IL23: 1004.46 | IM23: 1016.7 | IN23: 997.41 | IO23: 1014.3 | IP23: 1004.66 | IQ23: 1005.75 | IR23: 995.78
A24: 3.1.1.1. 주요국 통화의 대원화환율 | B24: 26 | C24: 원/뉴질랜드달러 | D24: 원 | E24: 원자료 | F24: 811.06 | G24: 828.26 | H24: 825.28 | I24: 824.54 | J24: 820.87 | K24: 817.49 | L24: 819.72 | M24: 821.88 | N24: 819.34 | O24: 823.52 | P24: 826.65 | Q24: 825.82 | R24: 823.67 | S24: 821.93 | T24: 830.53 | U24: 824.97 | V24: 818.86 | W24: 819.58 | X24: 815.91 | Y24: 810.71 | Z24: 819.13 | AA24: 827.23 | AB24: 834.29 | AC24: 827.26 | AD24: 825.26 | AE24: 825.98 | AF24: 833.12 | AG24: 832.94 | AH24: 827.51 | AI24: 837.31 | AJ24: 843.24 | AK24: 842 | AL24: 844.66 | AM24: 840.28 | AN24: 841.78 | AO24: 839.87 | AP24: 842.08 | AQ24: 837.05 | AR24: 841.06 | AS24: 836.56 | AT24: 834.42 | AU24: 839.68 | AV24: 837.23 | AW24: 848.73 | AX24: 800.61 | AY24: 812.04 | AZ24: 811.4 | BA24: 836.5 | BB24: 838.05 | BC24: 845.82 | BD24: 838.81 | BE24: 838.68 | BF24: 847.52 | BG24: 847.54 | BH24: 846.43 | BI24: 850.99 | BJ24: 847.66 | BK24: 848.97 | BL24: 857.26 | BM24: 854.16 | BN24: 859.62 | BO24: 853.25 | BP24: 842.51 | BQ24: 857.74 | BR24: 827.89 | BS24: 824.27 | BT24: 832.19 | BU24: 819.86 | BV24: 839.24 | BW24: 834.76 | BX24: 822.33 | BY24: 821.1 | BZ24: 828.8 | CA24: 825.39 | CB24: 822.9 | CC24: 812.84 | CD24: 825.52 | CE24: 818.8 | CF24: 814 | CG24: 820.84 | CH24: 825.73 | CI24: 822.26 | CJ24: 826.69 | CK24: 828.33 | CL24: 818.66 | CM24: 821.93 | CN24: 823.35 | CO24: 825.87 | CP24: 826.67 | CQ24: 821.58 | CR24: 826.48 | CS24: 818.65 | CT24: 827.9 | CU24: 827.35 | CV24: 815.96 | CW24: 827.48 | CX24: 820.16 | CY24: 822.87 | CZ24: 822.5 | DA24: 822.66 | DB24: 825.09 | DC24: 825.02 | DD24: 828.15 | DE24: 824.64 | DF24: 826.16 | DG24: 820.51 | DH24: 820.39 | DI24: 824.07 | DJ24: 829.64 | DK24: 824.48 | DL24: 823.24 | DM24: 822.43 | DN24: 824.63 | DO24: 826.48 | DP24: 827.9 | DQ24: 830.21 | DR24: 832.06 | DS24: 834.15 | DT24: 825.94 | DU24: 828.49 | DV24: 824.04 | DW24: 828.51 | DX24: 816.46 | DY24: 819.36 | DZ24: 826.92 | EA24: 819.03 | EB24: 819.33 | EC24: 824.6 | ED24: 825.68 | EE24: 824.88 | EF24: 824.51 | EG24: 827.93 | EH24: 826.96 | EI24: 819.51 | EJ24: 820.17 | EK24: 818.98 | EL24: 813.62 | EM24: 813.76 | EN24: 818.38 | EO24: 811.19 | EP24: 815.38 | EQ24: 817.81 | ER24: 816.77 | ES24: 818.12 | ET24: 821.86 | EU24: 816.32 | EV24: 819.48 | EW24: 814.38 | EX24: 819.21 | EY24: 826.11 | EZ24: 821.84 | FA24: 825.14 | FB24: 830.51 | FC24: 826.55 | FD24: 829.32 | FE24: 827.93 | FF24: 820.34 | FG24: 814.63 | FH24: 816.16 | FI24: 818.07 | FJ24: 816.63 | FK24: 811.27 | FL24: 807.54 | FM24: 814.99 | FN24: 810.19 | FO24: 813.79 | FP24: 818.43 | FQ24: 805.32 | FR24: 814.09 | FS24: 816.86 | FT24: 816.26 | FU24: 814.83 | FV24: 812.79 | FW24: 813.66 | FX24: 816.12 | FY24: 817.56 | FZ24: 820.52 | GA24: 826.55 | GB24: 827.41 | GC24: 827.41 | GD24: 829.03 | GE24: 825.62 | GF24: 817.06 | GG24: 816.62 | GH24: 815.53 | GI24: 811.15 | GJ24: 819.44 | GK24: 814.67 | GL24: 818.38 | GM24: 820.76 | GN24: 827.44 | GO24: 830.35 | GP24: 831 | GQ24: 828.06 | GR24: 825.03 | GS24: 829.38 | GT24: 821.43 | GU24: 819.66 | GV24: 826.31 | GW24: 827 | GX24: 828.92 | GY24: 833.67 | GZ24: 838.82 | HA24: 840.91 | HB24: 841.5 | HC24: 843.04 | HD24: 847.88 | HE24: 847.8 | HF24: 849.84 | HG24: 848.27 | HH24: 849.89 | HI24: 854.96 | HJ24: 853.49 | HK24: 853.76 | HL24: 852.91 | HM24: 851.42 | HN24: 853.52 | HO24: 853.3 | HP24: 850.55 | HQ24: 857.02 | HR24: 866.45 | HS24: 851.89 | HT24: 840.79 | HU24: 832.38 | HV24: 831.02 | HW24: 826 | HX24: 831.37 | HY24: 837.19 | HZ24: 836.48 | IA24: 836.18 | IB24: 833.62 | IC24: 834.19 | ID24: 845.08 | IE24: 845.61 | IF24: 848.9 | IG24: 843.98 | IH24: 847.63 | II24: 853.88 | IJ24: 860.72 | IK24: 860.04 | IL24: 868.49 | IM24: 876.58 | IN24: 861.5 | IO24: 874.28 | IP24: 864.87 | IQ24: 867.12 | IR24: 862.52
A25: 3.1.1.1. 주요국 통화의 대원화환율 | B25: 27 | C25: 원/중국위안 | D25: 원 | E25: 원자료
A26: 3.1.1.1. 주요국 통화의 대원화환율 | B26: 30 | C26: 원/홍콩위안 | D26: 원 | E26: 원자료
A27: 3.1.1.1. 주요국 통화의 대원화환율 | B27: 15 | C27: 원/홍콩달러 | D27: 원 | E27: 원자료 | F27: 186.42 | G27: 188.53 | H27: 187.59 | I27: 186.21 | J27: 185.84 | K27: 185.78 | L27: 186.6 | M27: 186.54 | N27: 186.47 | O27: 186.25 | P27: 185.42 | Q27: 185.23 | R27: 185.72 | S27: 185.23 | T27: 185.09 | U27: 184.59 | V27: 183.84 | W27: 184.04 | X27: 184.19 | Y27: 185.1 | Z27: 187.55 | AA27: 187.79 | AB27: 187.35 | AC27: 185.49 | AD27: 186.11 | AE27: 186.85 | AF27: 187.62 | AG27: 186.89 | AH27: 186.82 | AI27: 187.17 | AJ27: 186.37 | AK27: 186.25 | AL27: 186.91 | AM27: 187.74 | AN27: 188.71 | AO27: 188.69 | AP27: 189.01 | AQ27: 188.45 | AR27: 188.63 | AS27: 188.53 | AT27: 189.03 | AU27: 189.13 | AV27: 188.57 | AW27: 188.61 | AX27: 185.14 | AY27: 188.69 | AZ27: 189.2 | BA27: 191.06 | BB27: 187.98 | BC27: 187.07 | BD27: 184.06 | BE27: 183.48 | BF27: 183.89 | BG27: 182.9 | BH27: 183.15 | BI27: 182.87 | BJ27: 183.37 | BK27: 183.85 | BL27: 184.34 | BM27: 184.94 | BN27: 185.56 | BO27: 185.4 | BP27: 183.95 | BQ27: 184.06 | BR27: 179.67 | BS27: 179.57 | BT27: 180.73 | BU27: 179.74 | BV27: 181.32 | BW27: 181.39 | BX27: 179.31 | BY27: 178.43 | BZ27: 178.76 | CA27: 177.91 | CB27: 177.16 | CC27: 176.1 | CD27: 175.81 | CE27: 174.19 | CF27: 174.57 | CG27: 175.42 | CH27: 176.18 | CI27: 175.44 | CJ27: 175.51 | CK27: 175.14 | CL27: 173.19 | CM27: 173.16 | CN27: 173.28 | CO27: 174.4 | CP27: 173.64 | CQ27: 174.13 | CR27: 173.71 | CS27: 173.47 | CT27: 174.94 | CU27: 175.75 | CV27: 174.46 | CW27: 176.05 | CX27: 173.89 | CY27: 173.38 | CZ27: 172.96 | DA27: 172.8 | DB27: 172.44 | DC27: 172.34 | DD27: 173.18 | DE27: 173.07 | DF27: 173.79 | DG27: 174.09 | DH27: 174.27 | DI27: 175.01 | DJ27: 174.91 | DK27: 175.12 | DL27: 175.61 | DM27: 176.15 | DN27: 176.71 | DO27: 177.21 | DP27: 177.35 | DQ27: 177.22 | DR27: 176.6 | DS27: 175.69 | DT27: 174.36 | DU27: 175.3 | DV27: 175.76 | DW27: 177.25 | DX27: 176.18 | DY27: 177.13 | DZ27: 178.26 | EA27: 176.43 | EB27: 176.66 | EC27: 177.02 | ED27: 176.34 | EE27: 176.57 | EF27: 176.86 | EG27: 177.12 | EH27: 176.3 | EI27: 176.6 | EJ27: 177.16 | EK27: 178.16 | EL27: 178.89 | EM27: 178.92 | EN27: 178.56 | EO27: 177.46 | EP27: 178.5 | EQ27: 179.25 | ER27: 178.18 | ES27: 178.02 | ET27: 178.59 | EU27: 178.31 | EV27: 178.67 | EW27: 178.53 | EX27: 178.48 | EY27: 178.41 | EZ27: 178.04 | FA27: 178.13 | FB27: 178.39 | FC27: 178.49 | FD27: 178.6 | FE27: 177.67 | FF27: 177.43 | FG27: 178.03 | FH27: 179.25 | FI27: 179.41 | FJ27: 179.26 | FK27: 179.32 | FL27: 179.95 | FM27: 181.44 | FN27: 180.15 | FO27: 180.3 | FP27: 180.69 | FQ27: 180.15 | FR27: 182.53 | FS27: 183.52 | FT27: 183.74 | FU27: 183.2 | FV27: 182.62 | FW27: 182.75 | FX27: 182.81 | FY27: 183.19 | FZ27: 184.02 | GA27: 184.85 | GB27: 184.84 | GC27: 184.41 | GD27: 184.62 | GE27: 184.41 | GF27: 183.17 | GG27: 183.68 | GH27: 183.86 | GI27: 184.94 | GJ27: 186.12 | GK27: 185.91 | GL27: 186.96 | GM27: 187 | GN27: 188.27 | GO27: 188.7 | GP27: 189.11 | GQ27: 187.65 | GR27: 187.58 | GS27: 188.22 | GT27: 188.08 | GU27: 188.64 | GV27: 189.12 | GW27: 189.35 | GX27: 189.49 | GY27: 188.06 | GZ27: 188.31 | HA27: 188.29 | HB27: 188.63 | HC27: 188.8 | HD27: 188.69 | HE27: 189.07 | HF27: 189.1 | HG27: 188.8 | HH27: 188.94 | HI27: 189 | HJ27: 188.84 | HK27: 189.17 | HL27: 189.42 | HM27: 189.27 | HN27: 190.05 | HO27: 189.84 | HP27: 189.91 | HQ27: 190.08 | HR27: 190.73 | HS27: 187.84 | HT27: 185.6 | HU27: 184.46 | HV27: 184.41 | HW27: 184.31 | HX27: 185.09 | HY27: 185.84 | HZ27: 185.64 | IA27: 185.99 | IB27: 186.02 | IC27: 186.74 | ID27: 187.81 | IE27: 188.81 | IF27: 189.49 | IG27: 188.48 | IH27: 188.96 | II27: 189 | IJ27: 189.38 | IK27: 188.89 | IL27: 188.34 | IM27: 188.19 | IN27: 185.04 | IO27: 185.76 | IP27: 183.11 | IQ27: 182.81 | IR27: 183.9
A28: 3.1.1.1. 주요국 통화의 대원화환율 | B28: 31 | C28: 원/대만달러 | D28: 원 | E28: 원자료 | F28: 44.01 | G28: 44.52 | H28: 44.4 | I28: 44.16 | J28: 44.1 | K28: 44.1 | L28: 44.2 | M28: 44.28 | N28: 44.19 | O28: 44.45 | P28: 44.16 | Q28: 44.04 | R28: 44.1 | S28: 43.96 | T28: 44.01 | U28: 43.78 | V28: 43.68 | W28: 43.6 | X28: 43.69 | Y28: 43.74 | Z28: 44.33 | AA28: 44.49 | AB28: 44.35 | AC28: 43.84 | AD28: 44.04 | AE28: 44.14 | AF28: 44.34 | AG28: 44.11 | AH28: 44.02 | AI28: 44.16 | AJ28: 43.93 | AK28: 43.85 | AL28: 43.98 | AM28: 44.22 | AN28: 44.45 | AO28: 44.41 | AP28: 44.45 | AQ28: 44.26 | AR28: 44.28 | AS28: 44.17 | AT28: 44.22 | AU28: 44.31 | AV28: 44.14 | AW28: 44.39 | AX28: 43.4 | AY28: 44.43 | AZ28: 44.37 | BA28: 45.48 | BB28: 44.47 | BC28: 44.81 | BD28: 44.09 | BE28: 43.77 | BF28: 44.08 | BG28: 43.66 | BH28: 43.64 | BI28: 43.72 | BJ28: 43.65 | BK28: 43.83 | BL28: 44.08 | BM28: 44.1 | BN28: 44.37 | BO28: 44.48 | BP28: 44.42 | BQ28: 47.56 | BR28: 45.85 | BS28: 46.1 | BT28: 46.55 | BU28: 46.05 | BV28: 46.44 | BW28: 46.64 | BX28: 46.37 | BY28: 46.14 | BZ28: 46.35 | CA28: 46.18 | CB28: 46.18 | CC28: 45.85 | CD28: 45.92 | CE28: 45.61 | CF28: 45.64 | CG28: 45.96 | CH28: 46.3 | CI28: 46.03 | CJ28: 45.92 | CK28: 45.86 | CL28: 45.4 | CM28: 45.4 | CN28: 45.47 | CO28: 45.9 | CP28: 46.13 | CQ28: 46.25 | CR28: 46.35 | CS28: 45.91 | CT28: 46.46 | CU28: 46.63 | CV28: 46.34 | CW28: 46.53 | CX28: 46.31 | CY28: 46.34 | CZ28: 46.52 | DA28: 46.6 | DB28: 46.33 | DC28: 46.26 | DD28: 46.9 | DE28: 46.94 | DF28: 47.18 | DG28: 46.99 | DH28: 46.97 | DI28: 47.01 | DJ28: 46.93 | DK28: 47.03 | DL28: 46.97 | DM28: 47.03 | DN28: 47.17 | DO28: 47.27 | DP28: 47.35 | DQ28: 47.39 | DR28: 47.13 | DS28: 47.15 | DT28: 46.54 | DU28: 46.66 | DV28: 46.5 | DW28: 46.83 | DX28: 46.34 | DY28: 46.48 | DZ28: 46.91 | EA28: 46.32 | EB28: 46.3 | EC28: 46.45 | ED28: 46.43 | EE28: 46.41 | EF28: 46.33 | EG28: 46.5 | EH28: 46.19 | EI28: 46.07 | EJ28: 46.13 | EK28: 46.12 | EL28: 46.13 | EM28: 45.79 | EN28: 45.94 | EO28: 45.51 | EP28: 45.52 | EQ28: 45.63 | ER28: 45.52 | ES28: 45.39 | ET28: 45.46 | EU28: 45.26 | EV28: 45.35 | EW28: 45.35 | EX28: 45.64 | EY28: 45.81 | EZ28: 45.66 | FA28: 45.87 | FB28: 45.85 | FC28: 45.83 | FD28: 46 | FE28: 45.98 | FF28: 45.85 | FG28: 45.97 | FH28: 46.1 | FI28: 46.11 | FJ28: 46.02 | FK28: 45.92 | FL28: 45.81 | FM28: 46.34 | FN28: 46.01 | FO28: 46.07 | FP28: 46.16 | FQ28: 45.82 | FR28: 46.3 | FS28: 46.49 | FT28: 46.53 | FU28: 46.51 | FV28: 46.33 | FW28: 46.33 | FX28: 46.4 | FY28: 46.38 | FZ28: 46.49 | GA28: 46.66 | GB28: 46.55 | GC28: 46.79 | GD28: 46.94 | GE28: 46.7 | GF28: 46.29 | GG28: 46.36 | GH28: 46.2 | GI28: 46.48 | GJ28: 46.8 | GK28: 46.64 | GL28: 46.92 | GM28: 46.91 | GN28: 47.21 | GO28: 47.18 | GP28: 47.2 | GQ28: 47.6 | GR28: 46.76 | GS28: 47.09 | GT28: 46.95 | GU28: 46.81 | GV28: 46.95 | GW28: 46.86 | GX28: 46.92 | GY28: 46.79 | GZ28: 46.75 | HA28: 46.7 | HB28: 46.77 | HC28: 46.78 | HD28: 46.88 | HE28: 46.89 | HF28: 47.05 | HG28: 47.13 | HH28: 47.18 | HI28: 47.3 | HJ28: 47.08 | HK28: 46.96 | HL28: 47.03 | HM28: 46.77 | HN28: 46.71 | HO28: 46.85 | HP28: 46.89 | HQ28: 46.88 | HR28: 47.09 | HS28: 46.45 | HT28: 45.94 | HU28: 45.77 | HV28: 45.91 | HW28: 45.81 | HX28: 45.96 | HY28: 45.94 | HZ28: 45.88 | IA28: 46.03 | IB28: 45.93 | IC28: 46.05 | ID28: 46.36 | IE28: 46.56 | IF28: 46.87 | IG28: 46.54 | IH28: 46.6 | II28: 46.69 | IJ28: 46.52 | IK28: 46.53 | IL28: 46.46 | IM28: 46.76 | IN28: 45.87 | IO28: 46.49 | IP28: 45.65 | IQ28: 45.5 | IR28: 45.43
A29: 3.1.1.1. 주요국 통화의 대원화환율 | B29: 32 | C29: 원/몽골투그릭 | D29: 원 | E29: 원자료 | F29: 0.42 | G29: 0.43 | H29: 0.42 | I29: 0.42 | J29: 0.42 | K29: 0.42 | L29: 0.42 | M29: 0.42 | N29: 0.42 | O29: 0.42 | P29: 0.42 | Q29: 0.42 | R29: 0.42 | S29: 0.42 | T29: 0.42 | U29: 0.41 | V29: 0.41 | W29: 0.41 | X29: 0.41 | Y29: 0.41 | Z29: 0.42 | AA29: 0.42 | AB29: 0.42 | AC29: 0.42 | AD29: 0.42 | AE29: 0.42 | AF29: 0.42 | AG29: 0.42 | AH29: 0.42 | AI29: 0.42 | AJ29: 0.42 | AK29: 0.42 | AL29: 0.42 | AM29: 0.42 | AN29: 0.42 | AO29: 0.42 | AP29: 0.42 | AQ29: 0.42 | AR29: 0.42 | AS29: 0.42 | AT29: 0.42 | AU29: 0.42 | AV29: 0.42 | AW29: 0.42 | AX29: 0.41 | AY29: 0.42 | AZ29: 0.42 | BA29: 0.42 | BB29: 0.41 | BC29: 0.41 | BD29: 0.4 | BE29: 0.4 | BF29: 0.4 | BG29: 0.4 | BH29: 0.4 | BI29: 0.4 | BJ29: 0.4 | BK29: 0.4 | BL29: 0.4 | BM29: 0.4 | BN29: 0.4 | BO29: 0.4 | BP29: 0.4 | BQ29: 0.4 | BR29: 0.39 | BS29: 0.39 | BT29: 0.39 | BU29: 0.39 | BV29: 0.4 | BW29: 0.4 | BX29: 0.39 | BY29: 0.39 | BZ29: 0.39 | CA29: 0.39 | CB29: 0.39 | CC29: 0.39 | CD29: 0.38 | CE29: 0.38 | CF29: 0.38 | CG29: 0.38 | CH29: 0.39 | CI29: 0.38 | CJ29: 0.38 | CK29: 0.38 | CL29: 0.38 | CM29: 0.38 | CN29: 0.38 | CO29: 0.38 | CP29: 0.38 | CQ29: 0.38 | CR29: 0.38 | CS29: 0.38 | CT29: 0.38 | CU29: 0.38 | CV29: 0.38 | CW29: 0.39 | CX29: 0.38 | CY29: 0.38 | CZ29: 0.38 | DA29: 0.38 | DB29: 0.38 | DC29: 0.38 | DD29: 0.38 | DE29: 0.38 | DF29: 0.38 | DG29: 0.38 | DH29: 0.38 | DI29: 0.38 | DJ29: 0.38 | DK29: 0.38 | DL29: 0.38 | DM29: 0.39 | DN29: 0.39 | DO29: 0.39 | DP29: 0.39 | DQ29: 0.39 | DR29: 0.39 | DS29: 0.38 | DT29: 0.38 | DU29: 0.38 | DV29: 0.38 | DW29: 0.39 | DX29: 0.39 | DY29: 0.39 | DZ29: 0.39 | EA29: 0.39 | EB29: 0.39 | EC29: 0.39 | ED29: 0.39 | EE29: 0.39 | EF29: 0.39 | EG29: 0.39 | EH29: 0.38 | EI29: 0.38 | EJ29: 0.39 | EK29: 0.39 | EL29: 0.39 | EM29: 0.39 | EN29: 0.39 | EO29: 0.39 | EP29: 0.39 | EQ29: 0.39 | ER29: 0.39 | ES29: 0.39 | ET29: 0.39 | EU29: 0.39 | EV29: 0.39 | EW29: 0.39 | EX29: 0.39 | EY29: 0.39 | EZ29: 0.39 | FA29: 0.39 | FB29: 0.39 | FC29: 0.39 | FD29: 0.39 | FE29: 0.38 | FF29: 0.38 | FG29: 0.38 | FH29: 0.39 | FI29: 0.39 | FJ29: 0.39 | FK29: 0.39 | FL29: 0.39 | FM29: 0.39 | FN29: 0.39 | FO29: 0.39 | FP29: 0.39 | FQ29: 0.39 | FR29: 0.39 | FS29: 0.4 | FT29: 0.4 | FU29: 0.4 | FV29: 0.39 | FW29: 0.39 | FX29: 0.39 | FY29: 0.4 | FZ29: 0.4 | GA29: 0.4 | GB29: 0.4 | GC29: 0.4 | GD29: 0.4 | GE29: 0.4 | GF29: 0.4 | GG29: 0.4 | GH29: 0.4 | GI29: 0.4 | GJ29: 0.4 | GK29: 0.4 | GL29: 0.41 | GM29: 0.41 | GN29: 0.41 | GO29: 0.41 | GP29: 0.41 | GQ29: 0.41 | GR29: 0.41 | GS29: 0.41 | GT29: 0.41 | GU29: 0.41 | GV29: 0.41 | GW29: 0.41 | GX29: 0.41 | GY29: 0.41 | GZ29: 0.41 | HA29: 0.41 | HB29: 0.41 | HC29: 0.41 | HD29: 0.41 | HE29: 0.41 | HF29: 0.41 | HG29: 0.41 | HH29: 0.41 | HI29: 0.41 | HJ29: 0.41 | HK29: 0.42 | HL29: 0.42 | HM29: 0.41 | HN29: 0.42 | HO29: 0.42 | HP29: 0.42 | HQ29: 0.42 | HR29: 0.42 | HS29: 0.41 | HT29: 0.41 | HU29: 0.4 | HV29: 0.4 | HW29: 0.4 | HX29: 0.41 | HY29: 0.41 | HZ29: 0.41 | IA29: 0.41 | IB29: 0.41 | IC29: 0.41 | ID29: 0.41 | IE29: 0.41 | IF29: 0.41 | IG29: 0.41 | IH29: 0.41 | II29: 0.41 | IJ29: 0.41 | IK29: 0.41 | IL29: 0.41 | IM29: 0.41 | IN29: 0.4 | IO29: 0.41 | IP29: 0.4 | IQ29: 0.4 | IR29: 0.4
A30: 3.1.1.1. 주요국 통화의 대원화환율 | B30: 33 | C30: 원/카자흐스탄텡게 | D30: 원 | E30: 원자료 | F30: 2.8 | G30: 2.81 | H30: 2.81 | I30: 2.8 | J30: 2.82 | K30: 2.84 | L30: 2.86 | M30: 2.87 | N30: 2.88 | O30: 2.9 | P30: 2.9 | Q30: 2.9 | R30: 2.89 | S30: 2.87 | T30: 2.87 | U30: 2.83 | V30: 2.86 | W30: 2.87 | X30: 2.86 | Y30: 2.88 | Z30: 2.91 | AA30: 2.92 | AB30: 2.93 | AC30: 2.9 | AD30: 2.95 | AE30: 2.96 | AF30: 2.98 | AG30: 2.95 | AH30: 2.91 | AI30: 2.9 | AJ30: 2.9 | AK30: 2.91 | AL30: 2.88 | AM30: 2.9 | AN30: 2.92 | AO30: 2.92 | AP30: 2.92 | AQ30: 2.93 | AR30: 2.93 | AS30: 2.91 | AT30: 2.91 | AU30: 2.92 | AV30: 2.92 | AW30: 2.92 | AX30: 2.82 | AY30: 2.81 | AZ30: 2.84 | BA30: 2.85 | BB30: 2.83 | BC30: 2.8 | BD30: 2.76 | BE30: 2.75 | BF30: 2.72 | BG30: 2.71 | BH30: 2.72 | BI30: 2.73 | BJ30: 2.75 | BK30: 2.75 | BL30: 2.77 | BM30: 2.79 | BN30: 2.81 | BO30: 2.81 | BP30: 2.77 | BQ30: 2.77 | BR30: 2.71 | BS30: 2.7 | BT30: 2.72 | BU30: 2.73 | BV30: 2.78 | BW30: 2.79 | BX30: 2.74 | BY30: 2.74 | BZ30: 2.74 | CA30: 2.72 | CB30: 2.72 | CC30: 2.72 | CD30: 2.69 | CE30: 2.67 | CF30: 2.67 | CG30: 2.69 | CH30: 2.72 | CI30: 2.69 | CJ30: 2.69 | CK30: 2.69 | CL30: 2.66 | CM30: 2.67 | CN30: 2.67 | CO30: 2.68 | CP30: 2.66 | CQ30: 2.67 | CR30: 2.65 | CS30: 2.63 | CT30: 2.64 | CU30: 2.66 | CV30: 2.63 | CW30: 2.65 | CX30: 2.63 | CY30: 2.62 | CZ30: 2.62 | DA30: 2.61 | DB30: 2.61 | DC30: 2.61 | DD30: 2.62 | DE30: 2.61 | DF30: 2.63 | DG30: 2.63 | DH30: 2.63 | DI30: 2.65 | DJ30: 2.64 | DK30: 2.62 | DL30: 2.63 | DM30: 2.63 | DN30: 2.62 | DO30: 2.61 | DP30: 2.62 | DQ30: 2.62 | DR30: 2.59 | DS30: 2.56 | DT30: 2.52 | DU30: 2.52 | DV30: 2.54 | DW30: 2.56 | DX30: 2.55 | DY30: 2.57 | DZ30: 2.58 | EA30: 2.56 | EB30: 2.58 | EC30: 2.59 | ED30: 2.57 | EE30: 2.56 | EF30: 2.55 | EG30: 2.57 | EH30: 2.57 | EI30: 2.56 | EJ30: 2.57 | EK30: 2.58 | EL30: 2.6 | EM30: 2.6 | EN30: 2.6 | EO30: 2.59 | EP30: 2.6 | EQ30: 2.59 | ER30: 2.58 | ES30: 2.58 | ET30: 2.59 | EU30: 2.58 | EV30: 2.58 | EW30: 2.58 | EX30: 2.59 | EY30: 2.6 | EZ30: 2.58 | FA30: 2.58 | FB30: 2.57 | FC30: 2.57 | FD30: 2.57 | FE30: 2.56 | FF30: 2.55 | FG30: 2.56 | FH30: 2.57 | FI30: 2.57 | FJ30: 2.56 | FK30: 2.57 | FL30: 2.58 | FM30: 2.59 | FN30: 2.56 | FO30: 2.56 | FP30: 2.57 | FQ30: 2.59 | FR30: 2.64 | FS30: 2.66 | FT30: 2.65 | FU30: 2.64 | FV30: 2.65 | FW30: 2.64 | FX30: 2.64 | FY30: 2.64 | FZ30: 2.66 | GA30: 2.67 | GB30: 2.67 | GC30: 2.66 | GD30: 2.69 | GE30: 2.71 | GF30: 2.68 | GG30: 2.7 | GH30: 2.72 | GI30: 2.74 | GJ30: 2.76 | GK30: 2.75 | GL30: 2.77 | GM30: 2.77 | GN30: 2.79 | GO30: 2.79 | GP30: 2.8 | GQ30: 2.78 | GR30: 2.79 | GS30: 2.82 | GT30: 2.82 | GU30: 2.83 | GV30: 2.83 | GW30: 2.83 | GX30: 2.85 | GY30: 2.82 | GZ30: 2.84 | HA30: 2.86 | HB30: 2.88 | HC30: 2.9 | HD30: 2.92 | HE30: 2.91 | HF30: 2.91 | HG30: 2.88 | HH30: 2.85 | HI30: 2.84 | HJ30: 2.82 | HK30: 2.83 | HL30: 2.86 | HM30: 2.85 | HN30: 2.87 | HO30: 2.86 | HP30: 2.85 | HQ30: 2.87 | HR30: 2.91 | HS30: 2.86 | HT30: 2.85 | HU30: 2.86 | HV30: 2.86 | HW30: 2.83 | HX30: 2.84 | HY30: 2.82 | HZ30: 2.84 | IA30: 2.84 | IB30: 2.84 | IC30: 2.85 | ID30: 2.87 | IE30: 2.89 | IF30: 2.89 | IG30: 2.88 | IH30: 2.88 | II30: 2.89 | IJ30: 2.91 | IK30: 2.9 | IL30: 2.9 | IM30: 2.9 | IN30: 2.87 | IO30: 2.88 | IP30: 2.83 | IQ30: 2.84 | IR30: 2.85
